{
  "name": "Пример: Маленький дом",
  "dimensions": {
    "width": 7,
    "height": 5,
    "depth": 5
  },
  "blocks": [
    {"id": "minecraft:cobblestone", "x": 0, "y": 0, "z": 0},
    {"id": "minecraft:cobblestone", "x": 1, "y": 0, "z": 0},
    {"id": "minecraft:cobblestone", "x": 2, "y": 0, "z": 0},
    {"id": "minecraft:cobblestone", "x": 3, "y": 0, "z": 0},
    {"id": "minecraft:cobblestone", "x": 4, "y": 0, "z": 0},
    {"id": "minecraft:cobblestone", "x": 5, "y": 0, "z": 0},
    {"id": "minecraft:cobblestone", "x": 6, "y": 0, "z": 0},
    {"id": "minecraft:cobblestone", "x": 0, "y": 0, "z": 1},
    {"id": "minecraft:cobblestone", "x": 6, "y": 0, "z": 1},
    {"id": "minecraft:cobblestone", "x": 0, "y": 0, "z": 2},
    {"id": "minecraft:cobblestone", "x": 6, "y": 0, "z": 2},
    {"id": "minecraft:cobblestone", "x": 0, "y": 0, "z": 3},
    {"id": "minecraft:cobblestone", "x": 6, "y": 0, "z": 3},
    {"id": "minecraft:cobblestone", "x": 0, "y": 0, "z": 4},
    {"id": "minecraft:cobblestone", "x": 1, "y": 0, "z": 4},
    {"id": "minecraft:cobblestone", "x": 2, "y": 0, "z": 4},
    {"id": "minecraft:cobblestone", "x": 3, "y": 0, "z": 4},
    {"id": "minecraft:cobblestone", "x": 4, "y": 0, "z": 4},
    {"id": "minecraft:cobblestone", "x": 5, "y": 0, "z": 4},
    {"id": "minecraft:cobblestone", "x": 6, "y": 0, "z": 4},
    
    {"id": "minecraft:oak_planks", "x": 1, "y": 0, "z": 1},
    {"id": "minecraft:oak_planks", "x": 2, "y": 0, "z": 1},
    {"id": "minecraft:oak_planks", "x": 3, "y": 0, "z": 1},
    {"id": "minecraft:oak_planks", "x": 4, "y": 0, "z": 1},
    {"id": "minecraft:oak_planks", "x": 5, "y": 0, "z": 1},
    {"id": "minecraft:oak_planks", "x": 1, "y": 0, "z": 2},
    {"id": "minecraft:oak_planks", "x": 2, "y": 0, "z": 2},
    {"id": "minecraft:oak_planks", "x": 3, "y": 0, "z": 2},
    {"id": "minecraft:oak_planks", "x": 4, "y": 0, "z": 2},
    {"id": "minecraft:oak_planks", "x": 5, "y": 0, "z": 2},
    {"id": "minecraft:oak_planks", "x": 1, "y": 0, "z": 3},
    {"id": "minecraft:oak_planks", "x": 2, "y": 0, "z": 3},
    {"id": "minecraft:oak_planks", "x": 3, "y": 0, "z": 3},
    {"id": "minecraft:oak_planks", "x": 4, "y": 0, "z": 3},
    {"id": "minecraft:oak_planks", "x": 5, "y": 0, "z": 3},

    {"id": "minecraft:cobblestone", "x": 0, "y": 1, "z": 0},
    {"id": "minecraft:cobblestone", "x": 1, "y": 1, "z": 0},
    {"id": "minecraft:cobblestone", "x": 2, "y": 1, "z": 0},
    {"id": "minecraft:cobblestone", "x": 3, "y": 1, "z": 0},
    {"id": "minecraft:cobblestone", "x": 4, "y": 1, "z": 0},
    {"id": "minecraft:cobblestone", "x": 5, "y": 1, "z": 0},
    {"id": "minecraft:cobblestone", "x": 6, "y": 1, "z": 0},
    {"id": "minecraft:cobblestone", "x": 0, "y": 1, "z": 4},
    {"id": "minecraft:cobblestone", "x": 1, "y": 1, "z": 4},
    {"id": "minecraft:cobblestone", "x": 2, "y": 1, "z": 4},
    {"id": "minecraft:cobblestone", "x": 3, "y": 1, "z": 4},
    {"id": "minecraft:cobblestone", "x": 4, "y": 1, "z": 4},
    {"id": "minecraft:cobblestone", "x": 5, "y": 1, "z": 4},
    {"id": "minecraft:cobblestone", "x": 6, "y": 1, "z": 4},
    {"id": "minecraft:cobblestone", "x": 0, "y": 1, "z": 0},
    {"id": "minecraft:cobblestone", "x": 0, "y": 1, "z": 1},
    {"id": "minecraft:cobblestone", "x": 0, "y": 1, "z": 2},
    {"id": "minecraft:cobblestone", "x": 0, "y": 1, "z": 3},
    {"id": "minecraft:cobblestone", "x": 0, "y": 1, "z": 4},
    {"id": "minecraft:cobblestone", "x": 6, "y": 1, "z": 0},
    {"id": "minecraft:cobblestone", "x": 6, "y": 1, "z": 1},
    {"id": "minecraft:cobblestone", "x": 6, "y": 1, "z": 2},
    {"id": "minecraft:cobblestone", "x": 6, "y": 1, "z": 3},
    {"id": "minecraft:cobblestone", "x": 6, "y": 1, "z": 4},

    {"id": "minecraft:glass", "x": 1, "y": 1, "z": 0},
    {"id": "minecraft:glass", "x": 2, "y": 1, "z": 0},
    {"id": "minecraft:glass", "x": 4, "y": 1, "z": 0},
    {"id": "minecraft:glass", "x": 5, "y": 1, "z": 0},
    {"id": "minecraft:glass", "x": 1, "y": 1, "z": 4},
    {"id": "minecraft:glass", "x": 2, "y": 1, "z": 4},
    {"id": "minecraft:glass", "x": 4, "y": 1, "z": 4},
    {"id": "minecraft:glass", "x": 5, "y": 1, "z": 4},

    {"id": "minecraft:oak_door", "x": 3, "y": 1, "z": 4},

    {"id": "minecraft:cobblestone", "x": 0, "y": 2, "z": 0},
    {"id": "minecraft:cobblestone", "x": 1, "y": 2, "z": 0},
    {"id": "minecraft:cobblestone", "x": 2, "y": 2, "z": 0},
    {"id": "minecraft:cobblestone", "x": 3, "y": 2, "z": 0},
    {"id": "minecraft:cobblestone", "x": 4, "y": 2, "z": 0},
    {"id": "minecraft:cobblestone", "x": 5, "y": 2, "z": 0},
    {"id": "minecraft:cobblestone", "x": 6, "y": 2, "z": 0},
    {"id": "minecraft:cobblestone", "x": 0, "y": 2, "z": 4},
    {"id": "minecraft:cobblestone", "x": 1, "y": 2, "z": 4},
    {"id": "minecraft:cobblestone", "x": 2, "y": 2, "z": 4},
    {"id": "minecraft:cobblestone", "x": 3, "y": 2, "z": 4},
    {"id": "minecraft:cobblestone", "x": 4, "y": 2, "z": 4},
    {"id": "minecraft:cobblestone", "x": 5, "y": 2, "z": 4},
    {"id": "minecraft:cobblestone", "x": 6, "y": 2, "z": 4},
    {"id": "minecraft:cobblestone", "x": 0, "y": 2, "z": 0},
    {"id": "minecraft:cobblestone", "x": 0, "y": 2, "z": 1},
    {"id": "minecraft:cobblestone", "x": 0, "y": 2, "z": 2},
    {"id": "minecraft:cobblestone", "x": 0, "y": 2, "z": 3},
    {"id": "minecraft:cobblestone", "x": 0, "y": 2, "z": 4},
    {"id": "minecraft:cobblestone", "x": 6, "y": 2, "z": 0},
    {"id": "minecraft:cobblestone", "x": 6, "y": 2, "z": 1},
    {"id": "minecraft:cobblestone", "x": 6, "y": 2, "z": 2},
    {"id": "minecraft:cobblestone", "x": 6, "y": 2, "z": 3},
    {"id": "minecraft:cobblestone", "x": 6, "y": 2, "z": 4},

    {"id": "minecraft:glass", "x": 1, "y": 2, "z": 0},
    {"id": "minecraft:glass", "x": 2, "y": 2, "z": 0},
    {"id": "minecraft:glass", "x": 4, "y": 2, "z": 0},
    {"id": "minecraft:glass", "x": 5, "y": 2, "z": 0},
    {"id": "minecraft:glass", "x": 1, "y": 2, "z": 4},
    {"id": "minecraft:glass", "x": 2, "y": 2, "z": 4},
    {"id": "minecraft:glass", "x": 4, "y": 2, "z": 4},
    {"id": "minecraft:glass", "x": 5, "y": 2, "z": 4},

    {"id": "minecraft:cobblestone", "x": 0, "y": 3, "z": 0},
    {"id": "minecraft:cobblestone", "x": 1, "y": 3, "z": 0},
    {"id": "minecraft:cobblestone", "x": 2, "y": 3, "z": 0},
    {"id": "minecraft:cobblestone", "x": 3, "y": 3, "z": 0},
    {"id": "minecraft:cobblestone", "x": 4, "y": 3, "z": 0},
    {"id": "minecraft:cobblestone", "x": 5, "y": 3, "z": 0},
    {"id": "minecraft:cobblestone", "x": 6, "y": 3, "z": 0},
    {"id": "minecraft:cobblestone", "x": 0, "y": 3, "z": 4},
    {"id": "minecraft:cobblestone", "x": 1, "y": 3, "z": 4},
    {"id": "minecraft:cobblestone", "x": 2, "y": 3, "z": 4},
    {"id": "minecraft:cobblestone", "x": 3, "y": 3, "z": 4},
    {"id": "minecraft:cobblestone", "x": 4, "y": 3, "z": 4},
    {"id": "minecraft:cobblestone", "x": 5, "y": 3, "z": 4},
    {"id": "minecraft:cobblestone", "x": 6, "y": 3, "z": 4},
    {"id": "minecraft:cobblestone", "x": 0, "y": 3, "z": 0},
    {"id": "minecraft:cobblestone", "x": 0, "y": 3, "z": 1},
    {"id": "minecraft:cobblestone", "x": 0, "y": 3, "z": 2},
    {"id": "minecraft:cobblestone", "x": 0, "y": 3, "z": 3},
    {"id": "minecraft:cobblestone", "x": 0, "y": 3, "z": 4},
    {"id": "minecraft:cobblestone", "x": 6, "y": 3, "z": 0},
    {"id": "minecraft:cobblestone", "x": 6, "y": 3, "z": 1},
    {"id": "minecraft:cobblestone", "x": 6, "y": 3, "z": 2},
    {"id": "minecraft:cobblestone", "x": 6, "y": 3, "z": 3},
    {"id": "minecraft:cobblestone", "x": 6, "y": 3, "z": 4},

    {"id": "minecraft:torch", "x": 3, "y": 2, "z": 2},

    {"id": "minecraft:oak_stairs", "x": 0, "y": 4, "z": 0},
    {"id": "minecraft:oak_stairs", "x": 1, "y": 4, "z": 0},
    {"id": "minecraft:oak_stairs", "x": 2, "y": 4, "z": 0},
    {"id": "minecraft:oak_stairs", "x": 3, "y": 4, "z": 0},
    {"id": "minecraft:oak_stairs", "x": 4, "y": 4, "z": 0},
    {"id": "minecraft:oak_stairs", "x": 5, "y": 4, "z": 0},
    {"id": "minecraft:oak_stairs", "x": 6, "y": 4, "z": 0},
    {"id": "minecraft:oak_stairs", "x": 0, "y": 4, "z": 1},
    {"id": "minecraft:oak_stairs", "x": 0, "y": 4, "z": 2},
    {"id": "minecraft:oak_stairs", "x": 0, "y": 4, "z": 3},
    {"id": "minecraft:oak_stairs", "x": 0, "y": 4, "z": 4},
    {"id": "minecraft:oak_stairs", "x": 6, "y": 4, "z": 1},
    {"id": "minecraft:oak_stairs", "x": 6, "y": 4, "z": 2},
    {"id": "minecraft:oak_stairs", "x": 6, "y": 4, "z": 3},
    {"id": "minecraft:oak_stairs", "x": 6, "y": 4, "z": 4},
    {"id": "minecraft:oak_stairs", "x": 1, "y": 4, "z": 4},
    {"id": "minecraft:oak_stairs", "x": 2, "y": 4, "z": 4},
    {"id": "minecraft:oak_stairs", "x": 3, "y": 4, "z": 4},
    {"id": "minecraft:oak_stairs", "x": 4, "y": 4, "z": 4},
    {"id": "minecraft:oak_stairs", "x": 5, "y": 4, "z": 4}
  ]
}
